Workbook
Name ano_inicio: 'Valores base'!#REF!
Name cel_ano_inicio: 'Valores base'!$C$20
Name cel_conta_principal: 'Valores base'!$C$44
Name cel_data_fim: 'Valores base'!$C$22
Name cel_data_inicio: 'Valores base'!$C$4
Name cel_investimento: 'Valores base'!$C$18
Name cel_investimento_outros: 'Valores base'!$C$19
Name cel_lazer: 'Valores base'!$C$16
Name cel_lazer_outros: 'Valores base'!$C$17
Name cel_lista_categorias: 'Valores base'!$C$42
Name cel_lista_contas: 'Valores base'!$C$43
Name cel_necessidades_fixas: 'Valores base'!$C$5
Name cel_necessidades_fixas_aloc: 'Valores base'!$C$5
Name cel_necessidades_fixas_combustivel: 'Valores base'!$C$13
Name cel_necessidades_fixas_corrida: 'Valores base'!$C$11
Name cel_necessidades_fixas_estetica: 'Valores base'!$C$12
Name cel_necessidades_fixas_farmacia: 'Valores base'!$C$8
Name cel_necessidades_fixas_faxina: 'Valores base'!$C$9
Name cel_necessidades_fixas_mercado: 'Valores base'!$C$7
Name cel_necessidades_fixas_outros: 'Valores base'!$C$6
Name cel_necessidades_fixas_transporte: 'Valores base'!$C$10
Name cel_necessidades_ocasionais: 'Valores base'!$C$14
Name cel_necessidades_ocasionais_outros: 'Valores base'!$C$15
Name cel_patrimonio_atrasados: 'Valores base'!$C$37
Name cel_priodo_tamanho: 'Valores base'!$C$3
Name cel_recebiveis_adiantado: 'Valores base'!$C$35
Name cel_recebiveis_atrasados: 'Valores base'!$C$31
Name cel_recebiveis_atual: 'Valores base'!$C$32
Name cel_recebiveis_atual_concreto: 'Valores base'!$C$34
Name cel_recebiveis_atual_planejado: 'Valores base'!$C$33
Name cel_recebiveis_futuros: 'Valores base'!$C$36
Name cel_receita_total: 'Valores base'!$C$45
Name cel_semana: 'Valores base'!$C$21
Name cel_semana_atual: 'Valores base'!$C$47
Name cel_semana_atual_fim: 'Valores base'!$C$48
Name cel_semana1: 'Valores base'!$C$23
Name cel_semana1_perc: 'Valores base'!$C$27
Name cel_semana2: 'Valores base'!$C$24
Name cel_semana2_perc: 'Valores base'!$C$28
Name cel_semana3: 'Valores base'!$C$25
Name cel_semana3_perc: 'Valores base'!$C$29
Name cel_semana3_perf: 'Valores base'!$C$29
Name cel_semana4: 'Valores base'!$C$26
Name cel_semana4_perc: 'Valores base'!$C$30
Name celsemana: 'Valores base'!$C$21
Name col_semana_atual: 'Valores base'!$C$46
Name data_fim: 'Valores base'!#REF!
Name data_inicio: 'Valores base'!#REF!
Name data_inicio_old: 'Valores base'!#REF!
Name priodo_tamanho: 'Valores base'!$C$3
Name recebiveis_atrasado: Recebiveis!$F$1
Name recebiveis_atual: Recebiveis!$F$2
Name recebiveis_futuros: Recebiveis!$F$3
Name semana: 'Valores base'!#REF!
Name semana1: 'Valores base'!#REF!
Name semana1_perc: 'Valores base'!#REF!
Name semana2: 'Valores base'!#REF!
Name semana2_perc: 'Valores base'!#REF!
Name semana3: 'Valores base'!#REF!
Name semana3_perc: 'Valores base'!#REF!

Sheet Listas
A1: Categorias | B1: Contas
A2: {=_xlfn.TEXTSPLIT(cel_lista_categorias,,",")} -> Necessidades fixas[Outras] | B2: {=_xlfn.TEXTSPLIT(cel_lista_contas,,",")} -> Emprestimo BB
A3: Necessidades fixas[Mercado] | B3: Cartão BB
A4: Necessidades fixas[Farmácia] | B4: Conta BB[108376-7]
A5: Necessidades fixas[Faxina] | B5: Vargas1140-309
A6: Necessidades fixas[Transporte] | B6: Terrenos SPA
A7: Necessidades fixas[Corrida] | B7: Casa Joliva
A8: Necessidades fixas[Estetica] | B8: Veronica Nutri
A9: Necessidades fixas[Combustível] | B9: Santander
A10: Lazer[Outras]
A11: Necessidades ocasionais[Outras]
A12: Investimentos[Outros]
A13: Proventos[Outros]

Sheet Recebiveis - Resumo
A6: 1
A7: 2 | B7: 45723 | C7: ="IPTU Joliva " & A7 & " de 10 (Rafael)" -> IPTU Joliva 2 de 10 (Rafael) | D7: Patrimonio[Casa Joliva] | F7: 170.17
A8: 3 | B8: 45754 | C8: ="IPTU Joliva " & A8 & " de 10 (Rafael)" -> IPTU Joliva 3 de 10 (Rafael) | D8: Patrimonio[Casa Joliva] | F8: 170.17
A9: 4 | B9: 45784 | C9: ="IPTU Joliva " & A9 & " de 10 (Rafael)" -> IPTU Joliva 4 de 10 (Rafael) | D9: Patrimonio[Casa Joliva] | F9: 170.17
A10: 5 | B10: 45815 | C10: ="IPTU Joliva " & A10 & " de 10 (Rafael)" -> IPTU Joliva 5 de 10 (Rafael) | D10: Patrimonio[Casa Joliva] | F10: 170.17
A11: 6 | B11: 45845 | C11: ="IPTU Joliva " & A11 & " de 10 (Rafael)" -> IPTU Joliva 6 de 10 (Rafael) | D11: Patrimonio[Casa Joliva] | F11: 170.17
A12: 7 | B12: 45876 | C12: ="IPTU Joliva " & A12 & " de 10 (Rafael)" -> IPTU Joliva 7 de 10 (Rafael) | D12: Patrimonio[Casa Joliva] | F12: 170.17
A13: 8 | B13: 45907 | C13: ="IPTU Joliva " & A13 & " de 10 (Rafael)" -> IPTU Joliva 8 de 10 (Rafael) | D13: Patrimonio[Casa Joliva] | F13: 170.17
A14: 9 | B14: 45937 | C14: ="IPTU Joliva " & A14 & " de 10 (Rafael)" -> IPTU Joliva 9 de 10 (Rafael) | D14: Patrimonio[Casa Joliva] | F14: 170.17
A15: 10 | B15: 45968 | C15: ="IPTU Joliva " & A15 & " de 10 (Rafael)" -> IPTU Joliva 10 de 10 (Rafael) | D15: Patrimonio[Casa Joliva] | F15: 170.17
A16: 11
A17: 12
A18: 13
A19: 14
A20: 15
A21: 16
A22: 17
A23: 18
A24: 19
A25: 20
A26: 21
A27: 22
... A101: 96

Sheet Definições
B1: =CONCATENATE("Orçamento do mes ",MONTH(cel_data_inicio)," de ",cel_ano_inicio) -> Orçamento do mes 4 de 2026
C2: Data inicio: | D2: 46132 | E2: Dias: | F2: 30
C3: Necessidades ocasionais: | D3: 0.1 | E3: Investimento/Dividas: | F3: 0.05
C4: Necessidades fixas: | D4: 0.75 | E4: Lazer: | F4: 0.1
D5: {=_xlfn.CONCAT("Panorama até ",TEXT(INDIRECT(cel_semana_atual_fim),"dd/mm"))} -> Panorama até 20/05
B6: Categoria | C6: Planejado para o ciclo | D6: Reservado na semana | E6: Realizado na semana | F6: Saldo para semana
B7: Lazer[Outras] | C7: =cel_lazer_outros -> 1559.495 | D7: {=INDIRECT("'Panorama'!" & col_semana_atual & "4")} -> 308.555 | E7: {=INDIRECT("'Panorama'!" & CHAR(CODE(col_semana_atual)+1) & "4")} -> -181.6 | F7: {=INDIRECT("'Panorama'!" & CHAR(CODE(col_semana_atual)+2) & "4")} -> 126.955
B8: Investimentos[Outros] | C8: =cel_investimento_outros -> 779.7475 | D8: {=INDIRECT("'Panorama'!" & col_semana_atual & "5")} -> 264.2275 | E8: {=INDIRECT("'Panorama'!" & CHAR(CODE(col_semana_atual)+1) & "5")} -> 168.07 | F8: {=INDIRECT("'Panorama'!" & CHAR(CODE(col_semana_atual)+2) & "5")} -> 432.2975
B9: Necessidades ocasionais[Outras] | C9: =cel_necessidades_ocasionais_outros -> 1559.495 | D9: {=INDIRECT("'Panorama'!" & col_semana_atual & "6")} -> -162.035 | E9: {=INDIRECT("'Panorama'!" & CHAR(CODE(col_semana_atual)+1) & "6")} -> -2800 | F9: {=INDIRECT("'Panorama'!" & CHAR(CODE(col_semana_atual)+2) & "6")} -> -2962.035
B10: Necessidades fixas[Outras] | C10: =cel_necessidades_fixas_outros -> 8196.2125 | D10: {=INDIRECT("'Panorama'!" & col_semana_atual & "7")} -> 6663.1625 | E10: {=INDIRECT("'Panorama'!" & CHAR(CODE(col_semana_atual)+1) & "7")} -> -283.18 | F10: {=INDIRECT("'Panorama'!" & CHAR(CODE(col_semana_atual)+2) & "7")} -> 6379.9825
B11: Necessidades fixas[Mercado] | C11: 2000 | D11: {=INDIRECT("'Panorama'!" & col_semana_atual & "8")} -> 1208.86 | E11: {=INDIRECT("'Panorama'!" & CHAR(CODE(col_semana_atual)+1) & "8")} -> -620.93 | F11: {=INDIRECT("'Panorama'!" & CHAR(CODE(col_semana_atual)+2) & "8")} -> 587.93
B12: Necessidades fixas[Farmácia] | C12: 600 | D12: {=INDIRECT("'Panorama'!" & col_semana_atual & "9")} -> 381.08 | E12: {=INDIRECT("'Panorama'!" & CHAR(CODE(col_semana_atual)+1) & "9")} -> 0 | F12: {=INDIRECT("'Panorama'!" & CHAR(CODE(col_semana_atual)+2) & "9")} -> 381.08
B13: Necessidades fixas[Faxina] | C13: 0 | D13: {=INDIRECT("'Panorama'!" & col_semana_atual & "10")} -> 4015 | E13: {=INDIRECT("'Panorama'!" & CHAR(CODE(col_semana_atual)+1) & "10")} -> 0 | F13: {=INDIRECT("'Panorama'!" & CHAR(CODE(col_semana_atual)+2) & "10")} -> 4015
B14: Necessidades fixas[Transporte] | C14: 0 | D14: {=INDIRECT("'Panorama'!" & col_semana_atual & "11")} -> -159.45 | E14: {=INDIRECT("'Panorama'!" & CHAR(CODE(col_semana_atual)+1) & "11")} -> -93.9 | F14: {=INDIRECT("'Panorama'!" & CHAR(CODE(col_semana_atual)+2) & "11")} -> -253.35
B15: Necessidades fixas[Corrida] | C15: 0 | D15: {=INDIRECT("'Panorama'!" & col_semana_atual & "12")} -> 0 | E15: {=INDIRECT("'Panorama'!" & CHAR(CODE(col_semana_atual)+1) & "12")} -> 0 | F15: {=INDIRECT("'Panorama'!" & CHAR(CODE(col_semana_atual)+2) & "12")} -> 0
B16: Necessidades fixas[Estetica] | C16: 200 | D16: {=INDIRECT("'Panorama'!" & col_semana_atual & "13")} -> 145 | E16: {=INDIRECT("'Panorama'!" & CHAR(CODE(col_semana_atual)+1) & "13")} -> -60 | F16: {=INDIRECT("'Panorama'!" & CHAR(CODE(col_semana_atual)+2) & "13")} -> 85
B17: Necessidades fixas[Combustível] | C17: 700 | D17: {=INDIRECT("'Panorama'!" & col_semana_atual & "14")} -> 246.85 | E17: {=INDIRECT("'Panorama'!" & CHAR(CODE(col_semana_atual)+1) & "14")} -> -240.25 | F17: {=INDIRECT("'Panorama'!" & CHAR(CODE(col_semana_atual)+2) & "14")} -> 6.6
C18: =SUBTOTAL(109,Tabela3[Planejado para o ciclo]) -> 15594.95 | D18: =SUBTOTAL(109,Tabela3[Reservado na semana]) -> 12911.25 | E18: =SUBTOTAL(109,Tabela3[Realizado na semana]) -> -4111.79 | F18: =SUBTOTAL(109,Tabela3[Saldo para semana]) -> 8799.46

Sheet Panorama
B1: Panorama
B2: Categoria | C2: =_xlfn.CONCAT("Até: ",TEXT(cel_semana2,"dd/mm")) -> Até: 27/04 | F2: =_xlfn.CONCAT("Até: ",TEXT(cel_semana3,"dd/mm")) -> Até: 04/05 | I2: =_xlfn.CONCAT("Até: ",TEXT(cel_semana4,"dd/mm")) -> Até: 11/05 | L2: =_xlfn.CONCAT("Até: ",TEXT(cel_data_fim,"dd/mm")) -> Até: 20/05 | O2: Total
C3: Reservado | D3: Realizado | E3: Saldo | F3: Reservado | G3: Realizado | H3: Saldo | I3: Reservado | J3: Realizado | K3: Saldo | L3: Reservado | M3: Realizado | N3: Saldo | O3: Reservado | P3: Realizado | Q3: Saldo
B4: Lazer[Outras] | C4: =O4*cel_semana1_perc -> 363.88217 | D4: =SUMIFS(tb_recebiveis[valor],tb_recebiveis[Data],">=" & cel_semana1,tb_recebiveis[Data],"<" & cel_semana2,tb_recebiveis[Categoria],B4) -> -595.17 | E4: =C4+D4 -> -231.28783 | F4: =(O4*cel_semana2_perc)+IFERROR(E4/3,0) -> 286.78622 | G4: =SUMIFS(tb_recebiveis[valor],tb_recebiveis[Data],">=" & cel_semana2,tb_recebiveis[Data],"<" & cel_semana3,tb_recebiveis[Categoria],B4) -> -307.66 | H4: =(F4+G4) -> -20.873778 | I4: =(O4*cel_semana3_perc)+IFERROR(E4/3,0)+IFERROR(H4/2,0) -> 276.34933 | J4: =SUMIFS(tb_recebiveis[valor],tb_recebiveis[Data],">=" & cel_semana3,tb_recebiveis[Data],"<" & cel_semana4,tb_recebiveis[Categoria],B4) -> -348.11 | K4: =(I4+J4) -> -71.760667 | L4: =(O4*cel_semana4_perc)+IFERROR(E4/3,0)+IFERROR(H4/2,0)+K4 -> 308.555 | M4: =SUMIFS(tb_recebiveis[valor],tb_recebiveis[Data],">=" & cel_semana4,tb_recebiveis[Data],"<=" & cel_data_fim,tb_recebiveis[Categoria],B4) -> -181.6 | N4: =(L4+M4) -> 126.955 | O4: =cel_lazer_outros -> 1559.495 | P4: =D4+G4+J4+M4 -> -1432.54 | Q4: =O4+P4 -> 126.955
B5: Investimentos[Outros] | C5: =O5*cel_semana1_perc -> 181.94108 | D5: =SUMIFS(tb_recebiveis[valor],tb_recebiveis[Data],">=" & cel_semana1,tb_recebiveis[Data],"<" & cel_semana2,tb_recebiveis[Categoria],B5) -> -150 | E5: =C5+D5 -> 31.941083 | F5: =(O5*cel_semana2_perc)+IFERROR(E5/3,0) -> 192.58811 | G5: =SUMIFS(tb_recebiveis[valor],tb_recebiveis[Data],">=" & cel_semana2,tb_recebiveis[Data],"<" & cel_semana3,tb_recebiveis[Categoria],B5) -> -250 | H5: =(F5+G5) -> -57.411889 | I5: =(O5*cel_semana3_perc)+IFERROR(E5/3,0)+IFERROR(H5/2,0) -> 163.88217 | J5: =SUMIFS(tb_recebiveis[valor],tb_recebiveis[Data],">=" & cel_semana3,tb_recebiveis[Data],"<" & cel_semana4,tb_recebiveis[Categoria],B5) -> -115.52 | K5: =(I5+J5) -> 48.362167 | L5: =(O5*cel_semana4_perc)+IFERROR(E5/3,0)+IFERROR(H5/2,0)+K5 -> 264.2275 | M5: =SUMIFS(tb_recebiveis[valor],tb_recebiveis[Data],">=" & cel_semana4,tb_recebiveis[Data],"<=" & cel_data_fim,tb_recebiveis[Categoria],B5) -> 168.07 | N5: =(L5+M5) -> 432.2975 | O5: =cel_investimento_outros -> 779.7475 | P5: =D5+G5+J5+M5 -> -347.45 | Q5: =O5+P5 -> 432.2975
B6: Necessidades ocasionais[Outras] | C6: =O6*cel_semana1_perc -> 363.88217 | D6: =SUMIFS(tb_recebiveis[valor],tb_recebiveis[Data],">=" & cel_semana1,tb_recebiveis[Data],"<" & cel_semana2,tb_recebiveis[Categoria],B6) -> -1525.9 | E6: =C6+D6 -> -1162.0178 | F6: =(O6*cel_semana2_perc)+IFERROR(E6/3,0) -> -23.457111 | G6: =SUMIFS(tb_recebiveis[valor],tb_recebiveis[Data],">=" & cel_semana2,tb_recebiveis[Data],"<" & cel_semana3,tb_recebiveis[Categoria],B6) -> -232.68 | H6: =(F6+G6) -> -256.13711 | I6: =(O6*cel_semana3_perc)+IFERROR(E6/3,0)+IFERROR(H6/2,0) -> -151.52567 | J6: =SUMIFS(tb_recebiveis[valor],tb_recebiveis[Data],">=" & cel_semana3,tb_recebiveis[Data],"<" & cel_semana4,tb_recebiveis[Categoria],B6) -> 37.05 | K6: =(I6+J6) -> -114.47567 | L6: =(O6*cel_semana4_perc)+IFERROR(E6/3,0)+IFERROR(H6/2,0)+K6 -> -162.035 | M6: =SUMIFS(tb_recebiveis[valor],tb_recebiveis[Data],">=" & cel_semana4,tb_recebiveis[Data],"<=" & cel_data_fim,tb_recebiveis[Categoria],B6) -> -2800 | N6: =(L6+M6) -> -2962.035 | O6: =cel_necessidades_ocasionais_outros -> 1559.495 | P6: =D6+G6+J6+M6 -> -4521.53 | Q6: =O6+P6 -> -2962.035
B7: Necessidades fixas[Outras] | C7: =O7*cel_semana1_perc -> 1912.4496 | D7: =SUMIFS(tb_recebiveis[valor],tb_recebiveis[Data],">=" & cel_semana1,tb_recebiveis[Data],"<" & cel_semana2,tb_recebiveis[Categoria],B7) -> -106.9 | E7: =C7+D7 -> 1805.5496 | F7: =(O7*cel_semana2_perc)+IFERROR(E7/3,0) -> 2514.2994 | G7: =SUMIFS(tb_recebiveis[valor],tb_recebiveis[Data],">=" & cel_semana2,tb_recebiveis[Data],"<" & cel_semana3,tb_recebiveis[Categoria],B7) -> -156.81 | H7: =(F7+G7) -> 2357.4894 | I7: =(O7*cel_semana3_perc)+IFERROR(E7/3,0)+IFERROR(H7/2,0) -> 3693.0442 | J7: =SUMIFS(tb_recebiveis[valor],tb_recebiveis[Data],">=" & cel_semana3,tb_recebiveis[Data],"<" & cel_semana4,tb_recebiveis[Categoria],B7) -> -1269.34 | K7: =(I7+J7) -> 2423.7042 | L7: =(O7*cel_semana4_perc)+IFERROR(E7/3,0)+IFERROR(H7/2,0)+K7 -> 6663.1625 | M7: =SUMIFS(tb_recebiveis[valor],tb_recebiveis[Data],">=" & cel_semana4,tb_recebiveis[Data],"<=" & cel_data_fim,tb_recebiveis[Categoria],B7) -> -283.18 | N7: =(L7+M7) -> 6379.9825 | O7: =cel_necessidades_fixas_outros -> 8196.2125 | P7: =D7+G7+J7+M7 -> -1816.23 | Q7: =O7+P7 -> 6379.9825
B8: Necessidades fixas[Mercado] | C8: =O8*cel_semana1_perc -> 466.66667 | D8: =SUMIFS(tb_recebiveis[valor],tb_recebiveis[Data],">=" & cel_semana1,tb_recebiveis[Data],"<" & cel_semana2,tb_recebiveis[Categoria],B8) -> -540.59 | E8: =C8+D8 -> -73.923333 | F8: =(O8*cel_semana2_perc)+IFERROR(E8/3,0) -> 442.02556 | G8: =SUMIFS(tb_recebiveis[valor],tb_recebiveis[Data],">=" & cel_semana2,tb_recebiveis[Data],"<" & cel_semana3,tb_recebiveis[Categoria],B8) -> -105.24 | H8: =(F8+G8) -> 336.78556 | I8: =(O8*cel_semana3_perc)+IFERROR(E8/3,0)+IFERROR(H8/2,0) -> 610.41833 | J8: =SUMIFS(tb_recebiveis[valor],tb_recebiveis[Data],">=" & cel_semana3,tb_recebiveis[Data],"<" & cel_semana4,tb_recebiveis[Categoria],B8) -> -145.31 | K8: =(I8+J8) -> 465.10833 | L8: =(O8*cel_semana4_perc)+IFERROR(E8/3,0)+IFERROR(H8/2,0)+K8 -> 1208.86 | M8: =SUMIFS(tb_recebiveis[valor],tb_recebiveis[Data],">=" & cel_semana4,tb_recebiveis[Data],"<=" & cel_data_fim,tb_recebiveis[Categoria],B8) -> -620.93 | N8: =(L8+M8) -> 587.93 | O8: =cel_necessidades_fixas_mercado -> 2000 | P8: =D8+G8+J8+M8 -> -1412.07 | Q8: =O8+P8 -> 587.93
B9: Necessidades fixas[Farmácia] | C9: =O9*cel_semana1_perc -> 140 | D9: =SUMIFS(tb_recebiveis[valor],tb_recebiveis[Data],">=" & cel_semana1,tb_recebiveis[Data],"<" & cel_semana2,tb_recebiveis[Categoria],B9) -> -90.47 | E9: =C9+D9 -> 49.53 | F9: =(O9*cel_semana2_perc)+IFERROR(E9/3,0) -> 156.51 | G9: =SUMIFS(tb_recebiveis[valor],tb_recebiveis[Data],">=" & cel_semana2,tb_recebiveis[Data],"<" & cel_semana3,tb_recebiveis[Categoria],B9) -> 0 | H9: =(F9+G9) -> 156.51 | I9: =(O9*cel_semana3_perc)+IFERROR(E9/3,0)+IFERROR(H9/2,0) -> 234.765 | J9: =SUMIFS(tb_recebiveis[valor],tb_recebiveis[Data],">=" & cel_semana3,tb_recebiveis[Data],"<" & cel_semana4,tb_recebiveis[Categoria],B9) -> -128.45 | K9: =(I9+J9) -> 106.315 | L9: =(O9*cel_semana4_perc)+IFERROR(E9/3,0)+IFERROR(H9/2,0)+K9 -> 381.08 | M9: =SUMIFS(tb_recebiveis[valor],tb_recebiveis[Data],">=" & cel_semana4,tb_recebiveis[Data],"<=" & cel_data_fim,tb_recebiveis[Categoria],B9) -> 0 | N9: =(L9+M9) -> 381.08 | O9: =cel_necessidades_fixas_farmacia -> 600 | P9: =D9+G9+J9+M9 -> -218.92 | Q9: =O9+P9 -> 381.08
B10: Necessidades fixas[Faxina] | C10: =O10*cel_semana1_perc -> 0 | D10: =SUMIFS(tb_recebiveis[valor],tb_recebiveis[Data],">=" & cel_semana1,tb_recebiveis[Data],"<" & cel_semana2,tb_recebiveis[Categoria],B10) -> 0 | E10: =C10+D10 -> 0 | F10: =(O10*cel_semana2_perc)+IFERROR(E10/3,0) -> 0 | G10: =SUMIFS(tb_recebiveis[valor],tb_recebiveis[Data],">=" & cel_semana2,tb_recebiveis[Data],"<" & cel_semana3,tb_recebiveis[Categoria],B10) -> 4015 | H10: =(F10+G10) -> 4015 | I10: =(O10*cel_semana3_perc)+IFERROR(E10/3,0)+IFERROR(H10/2,0) -> 2007.5 | J10: =SUMIFS(tb_recebiveis[valor],tb_recebiveis[Data],">=" & cel_semana3,tb_recebiveis[Data],"<" & cel_semana4,tb_recebiveis[Categoria],B10) -> 0 | K10: =(I10+J10) -> 2007.5 | L10: =(O10*cel_semana4_perc)+IFERROR(E10/3,0)+IFERROR(H10/2,0)+K10 -> 4015 | M10: =SUMIFS(tb_recebiveis[valor],tb_recebiveis[Data],">=" & cel_semana4,tb_recebiveis[Data],"<=" & cel_data_fim,tb_recebiveis[Categoria],B10) -> 0 | N10: =(L10+M10) -> 4015 | O10: =cel_necessidades_fixas_faxina -> 0 | P10: =D10+G10+J10+M10 -> 4015 | Q10: =O10+P10 -> 4015
B11: Necessidades fixas[Transporte] | C11: =O11*cel_semana1_perc -> 0 | D11: =SUMIFS(tb_recebiveis[valor],tb_recebiveis[Data],">=" & cel_semana1,tb_recebiveis[Data],"<" & cel_semana2,tb_recebiveis[Categoria],B11) -> -50.55 | E11: =C11+D11 -> -50.55 | F11: =(O11*cel_semana2_perc)+IFERROR(E11/3,0) -> -16.85 | G11: =SUMIFS(tb_recebiveis[valor],tb_recebiveis[Data],">=" & cel_semana2,tb_recebiveis[Data],"<" & cel_semana3,tb_recebiveis[Categoria],B11) -> -20 | H11: =(F11+G11) -> -36.85 | I11: =(O11*cel_semana3_perc)+IFERROR(E11/3,0)+IFERROR(H11/2,0) -> -35.275 | J11: =SUMIFS(tb_recebiveis[valor],tb_recebiveis[Data],">=" & cel_semana3,tb_recebiveis[Data],"<" & cel_semana4,tb_recebiveis[Categoria],B11) -> -88.9 | K11: =(I11+J11) -> -124.175 | L11: =(O11*cel_semana4_perc)+IFERROR(E11/3,0)+IFERROR(H11/2,0)+K11 -> -159.45 | M11: =SUMIFS(tb_recebiveis[valor],tb_recebiveis[Data],">=" & cel_semana4,tb_recebiveis[Data],"<=" & cel_data_fim,tb_recebiveis[Categoria],B11) -> -93.9 | N11: =(L11+M11) -> -253.35 | O11: =cel_necessidades_fixas_transporte -> 0 | P11: =D11+G11+J11+M11 -> -253.35 | Q11: =O11+P11 -> -253.35
B12: Necessidades fixas[Corrida] | C12: =O12*cel_semana1_perc -> 0 | D12: =SUMIFS(tb_recebiveis[valor],tb_recebiveis[Data],">=" & cel_semana1,tb_recebiveis[Data],"<" & cel_semana2,tb_recebiveis[Categoria],B12) -> 0 | E12: =C12+D12 -> 0 | F12: =(O12*cel_semana2_perc)+IFERROR(E12/3,0) -> 0 | G12: =SUMIFS(tb_recebiveis[valor],tb_recebiveis[Data],">=" & cel_semana2,tb_recebiveis[Data],"<" & cel_semana3,tb_recebiveis[Categoria],B12) -> 0 | H12: =(F12+G12) -> 0 | I12: =(O12*cel_semana3_perc)+IFERROR(E12/3,0)+IFERROR(H12/2,0) -> 0 | J12: =SUMIFS(tb_recebiveis[valor],tb_recebiveis[Data],">=" & cel_semana3,tb_recebiveis[Data],"<" & cel_semana4,tb_recebiveis[Categoria],B12) -> 0 | K12: =(I12+J12) -> 0 | L12: =(O12*cel_semana4_perc)+IFERROR(E12/3,0)+IFERROR(H12/2,0)+K12 -> 0 | M12: =SUMIFS(tb_recebiveis[valor],tb_recebiveis[Data],">=" & cel_semana4,tb_recebiveis[Data],"<=" & cel_data_fim,tb_recebiveis[Categoria],B12) -> 0 | N12: =(L12+M12) -> 0 | O12: =cel_necessidades_fixas_corrida -> 0 | P12: =D12+G12+J12+M12 -> 0 | Q12: =O12+P12 -> 0
B13: Necessidades fixas[Estetica] | C13: =O13*cel_semana1_perc -> 46.666667 | D13: =SUMIFS(tb_recebiveis[valor],tb_recebiveis[Data],">=" & cel_semana1,tb_recebiveis[Data],"<" & cel_semana2,tb_recebiveis[Categoria],B13) -> 0 | E13: =C13+D13 -> 46.666667 | F13: =(O13*cel_semana2_perc)+IFERROR(E13/3,0) -> 62.222222 | G13: =SUMIFS(tb_recebiveis[valor],tb_recebiveis[Data],">=" & cel_semana2,tb_recebiveis[Data],"<" & cel_semana3,tb_recebiveis[Categoria],B13) -> 0 | H13: =(F13+G13) -> 62.222222 | I13: =(O13*cel_semana3_perc)+IFERROR(E13/3,0)+IFERROR(H13/2,0) -> 93.333333 | J13: =SUMIFS(tb_recebiveis[valor],tb_recebiveis[Data],">=" & cel_semana3,tb_recebiveis[Data],"<" & cel_semana4,tb_recebiveis[Categoria],B13) -> -55 | K13: =(I13+J13) -> 38.333333 | L13: =(O13*cel_semana4_perc)+IFERROR(E13/3,0)+IFERROR(H13/2,0)+K13 -> 145 | M13: =SUMIFS(tb_recebiveis[valor],tb_recebiveis[Data],">=" & cel_semana4,tb_recebiveis[Data],"<=" & cel_data_fim,tb_recebiveis[Categoria],B13) -> -60 | N13: =(L13+M13) -> 85 | O13: =cel_necessidades_fixas_estetica -> 200 | P13: =D13+G13+J13+M13 -> -115 | Q13: =O13+P13 -> 85
B14: Necessidades fixas[Combustível] | C14: =O14*cel_semana1_perc -> 163.33333 | D14: =SUMIFS(tb_recebiveis[valor],tb_recebiveis[Data],">=" & cel_semana1,tb_recebiveis[Data],"<" & cel_semana2,tb_recebiveis[Categoria],B14) -> 0 | E14: =C14+D14 -> 163.33333 | F14: =(O14*cel_semana2_perc)+IFERROR(E14/3,0) -> 217.77778 | G14: =SUMIFS(tb_recebiveis[valor],tb_recebiveis[Data],">=" & cel_semana2,tb_recebiveis[Data],"<" & cel_semana3,tb_recebiveis[Categoria],B14) -> -264.16 | H14: =(F14+G14) -> -46.382222 | I14: =(O14*cel_semana3_perc)+IFERROR(E14/3,0)+IFERROR(H14/2,0) -> 194.58667 | J14: =SUMIFS(tb_recebiveis[valor],tb_recebiveis[Data],">=" & cel_semana3,tb_recebiveis[Data],"<" & cel_semana4,tb_recebiveis[Categoria],B14) -> -188.99 | K14: =(I14+J14) -> 5.5966667 | L14: =(O14*cel_semana4_perc)+IFERROR(E14/3,0)+IFERROR(H14/2,0)+K14 -> 246.85 | M14: =SUMIFS(tb_recebiveis[valor],tb_recebiveis[Data],">=" & cel_semana4,tb_recebiveis[Data],"<=" & cel_data_fim,tb_recebiveis[Categoria],B14) -> -240.25 | N14: =(L14+M14) -> 6.6 | O14: =cel_necessidades_fixas_combustivel -> 700 | P14: =D14+G14+J14+M14 -> -693.4 | Q14: =O14+P14 -> 6.6
B15: Total | C15: =SUM(C4:C14) -> 3638.8217 | D15: =SUM(D4:D14) -> -3059.58 | E15: =SUM(E4:E14) -> 579.24167 | F15: =SUM(F4:F14) -> 3831.9022 | G15: =SUM(G4:G14) -> 2678.45 | H15: =SUM(H4:H14) -> 6510.3522 | I15: =SUM(I4:I14) -> 7087.0783 | J15: =SUM(J4:J14) -> -2302.57 | ... Q15: =SUM(Q4:Q14) -> 8799.46

Sheet Recebiveis
B1: Recebíveis | E1: =_xlfn.CONCAT("Atrasados (antes de ",TEXT(Definições!D2,"dd/mm/aa"),"):") -> Atrasados (antes de 20/04/26): | F1: =cel_recebiveis_atrasados -> 0
E2: Atual: | F2: =cel_recebiveis_atual_concreto+cel_recebiveis_atual_planejado -> 0
E3: =_xlfn.CONCAT("Futuros (depois de ",TEXT(Definições!#REF!,"dd/mm/aa"),"):") -> #REF! | F3: =cel_recebiveis_futuros -> 0
B4: Data | C4: item | D4: Conta | E4: Categoria | F4: Recebido | G4: valor
B5: 44645 | C5: Emprestimo BB (Valor recebido) | D5: Emprestimo BB | E5: Necessidades fixas[Outras] | F5: 44645 | G5: 90000
B6: 44676 | C6: Emprestimo BB 1 de 96 | D6: Emprestimo BB | E6: Necessidades fixas[Outras] | F6: 44676 | G6: -1863.6
B7: 44706 | C7: Emprestimo BB 2 de 96 | D7: Emprestimo BB | E7: Necessidades fixas[Outras] | F7: 44706 | G7: -1863.6
B8: 44737 | C8: Emprestimo BB 3 de 96 | D8: Emprestimo BB | E8: Necessidades fixas[Outras] | F8: 44737 | G8: -1863.6
B9: 44767 | C9: Emprestimo BB 4 de 96 | D9: Emprestimo BB | E9: Necessidades fixas[Outras] | F9: 44767 | G9: -1863.6
B10: 44798 | C10: Emprestimo BB 5 de 96 | D10: Emprestimo BB | E10: Necessidades fixas[Outras] | F10: 44798 | G10: -1863.6
B11: 44829 | C11: Emprestimo BB 6 de 96 | D11: Emprestimo BB | E11: Necessidades fixas[Outras] | F11: 44829 | G11: -1863.6
B12: 44859 | C12: Emprestimo BB 7 de 96 | D12: Emprestimo BB | E12: Necessidades fixas[Outras] | F12: 44859 | G12: -1863.6
B13: 44890 | C13: Emprestimo BB 8 de 96 | D13: Emprestimo BB | E13: Necessidades fixas[Outras] | F13: 44890 | G13: -1863.6
B14: 44920 | C14: Emprestimo BB 9 de 96 | D14: Emprestimo BB | E14: Necessidades fixas[Outras] | F14: 44920 | G14: -1863.6
B15: 44951 | C15: Emprestimo BB 10 de 96 | D15: Emprestimo BB | E15: Necessidades fixas[Outras] | F15: 44951 | G15: -1863.6
B16: 44982 | C16: Emprestimo BB 11 de 96 | D16: Emprestimo BB | E16: Necessidades fixas[Outras] | F16: 44982 | G16: -1863.6
... B42: 45713 | C42: Emprestimo BB 35 de 96 | D42: Emprestimo BB | E42: Necessidades fixas[Outras] | F42: 45713 | G42: -1863.6
B43: 45716 | C43: IPTU Joliva 1 de 10 | D43: Casa Joliva | E43: Necessidades fixas[Outras] | G43: -510.51
B44: 45716 | C44: IPTU Joliva 1 de 10 (Rita) | D44: Casa Joliva | E44: Proventos[Outros] | G44: 170.17
B45: 45716 | C45: IPTU Joliva 1 de 10 (Rafael) | D45: Casa Joliva | E45: Proventos[Outros] | G45: 170.17
B46: 45716 | C46: IPTU Joliva 1 de 10 (Rodrigo) | D46: Casa Joliva | E46: Proventos[Outros] | G46: 170.17
B47: 45716 | C47: IPTU SPA | D47: Terrenos SPA | E47: Necessidades fixas[Outras] | G47: -1232.59
B48: 45723 | C48: IPTU Joliva 2 de 10 (Rita) | D48: Casa Joliva | E48: Proventos[Outros] | G48: 170.17
B49: 45723 | C49: IPTU Joliva 2 de 10 (Rafael) | D49: Casa Joliva | E49: Proventos[Outros] | G49: 170.17
B50: 45723 | C50: IPTU Joliva 2 de 10 (Rodrigo) | D50: Casa Joliva | E50: Proventos[Outros] | G50: 170.17
B51: 45723 | C51: IPTU Joliva 2 de 10 | D51: Casa Joliva | E51: Necessidades fixas[Outras] | G51: -510.51
B52: 45728 | C52: Aluguel Joliva | D52: Conta BB[108376-7] | E52: Proventos[Outros] | F52: 45728 | G52: 1904.7
B53: 45741 | C53: Emprestimo BB 36 de 96 | D53: Emprestimo BB | E53: Necessidades fixas[Outras] | F53: 45741 | G53: -1863.6
B54: 45754 | C54: IPTU Joliva 3 de 10 (Rita) | D54: Casa Joliva | E54: Proventos[Outros] | G54: 170.17
B55: 45754 | C55: IPTU Joliva 3 de 10 (Rafael) | D55: Casa Joliva | E55: Proventos[Outros] | G55: 170.17
B56: 45754 | C56: IPTU Joliva 3 de 10 (Rodrigo) | D56: Casa Joliva | E56: Proventos[Outros] | G56: 170.17
B57: 45759 | C57: Aluguel Joliva | D57: Conta BB[108376-7] | E57: Proventos[Outros] | F57: 45759 | G57: 1904.7
B58: 45772 | C58: Emprestimo BB 37 de 96 | D58: Emprestimo BB | E58: Necessidades fixas[Outras] | F58: 45772 | G58: -1863.6
B59: 45775 | C59: IPTU Joliva 3 de 10 | D59: Casa Joliva | E59: Necessidades fixas[Outras] | G59: -510.51
B60: 45780 | C60: Ajuda Lélia | D60: Conta BB[108376-7] | E60: Proventos[Outros] | G60: 1000
B61: 45784 | C61: IPTU Joliva 4 de 10 (Rita) | D61: Casa Joliva | E61: Proventos[Outros] | G61: 170.17
B62: 45784 | C62: IPTU Joliva 4 de 10 (Rafael) | D62: Casa Joliva | E62: Proventos[Outros] | G62: 170.17
B63: 45784 | C63: IPTU Joliva 4 de 10 (Rodrigo) | D63: Casa Joliva | E63: Proventos[Outros] | G63: 170.17
B64: 45789 | C64: Aluguel Joliva | D64: Conta BB[108376-7] | E64: Proventos[Outros] | F64: 45789 | G64: 1904.7
B65: 45790 | C65: Prestação durante obras 1 | D65: Vargas1140-309 | E65: Necessidades fixas[Outras] | G65: -2296.72
...

Sheet Valores base
B2: Variavel | C2: Valor | D2: Descrição
B3: periodo_tamanho | C3: =Definições!F2 -> 30 | D3: Numero de dias do periodo
B4: data_inicio | C4: =Definições!D2 -> 46132 | D4: Data de iniciodo periodo
B5: Necessidades fixas | C5: =Definições!D4 -> 0.75 | D5: Percentual de alocação de recursos de recebiveis para necessidades fixas
B6: Necessidades fixas[Outros] | C6: =(cel_necessidades_fixas*cel_receita_total)-(cel_necessidades_fixas_combustivel+cel_necessidades_fixas_estetica+cel_necessidades_fixas_corrida+cel_necessidades_fixas_farmacia+cel_necessidades_fixas_faxina+cel_necessidades_fixas_mercado) -> 8196.2125 | D6: Valor bruto reservado para as demais necessidades fixas
B7: Necessidades fixas[Mercado] | C7: =Definições!C11 -> 2000 | D7: Valor bruto reservado para mercado de despeza fixa
B8: Necessidades fixas[Farmácia] | C8: =Definições!C12 -> 600 | D8: Valor bruto reservado para farmacia de despeza fixa
B9: Necessidades fixas[Faxina] | C9: =Definições!C13 -> 0 | D9: Valor bruto reservado para faxina de despeza fixa
B10: Necessidades fixas[Transporte] | C10: =Definições!C14 -> 0 | D10: Valor bruto reservado para transporte de despeza fixa
B11: Necessidades fixas[Corrida] | C11: =Definições!C15 -> 0 | D11: Valor bruto reservado para corrida de despeza fixa
B12: Necessidades fixas[Estetica] | C12: =Definições!C16 -> 200 | D12: Valor bruto reservado para estética de despeza fixa
B13: Necessidades fixas[Combustível] | C13: =Definições!C17 -> 700 | D13: Valor bruto reservado para combustivel de despeza fixa
B14: Necessidades ocasionais | C14: =Definições!D3 -> 0.1 | D14: Percentual de alocação de recebiveis para necessidades ocasionais
B15: Necessidades ocasionais[Outros] | C15: =cel_necessidades_ocasionais*cel_receita_total -> 1559.495 | D15: Valor bruto reservado para as demais necessidades ocasionais
B16: Lazer | C16: =Definições!F4 -> 0.1 | D16: Percentual de alocação de recebiveis para lazer
B17: Lazer[Outros] | C17: =cel_lazer*cel_receita_total -> 1559.495 | D17: Valor bruto reservado para os demais valores lazer
B18: Investimento | C18: =Definições!F3 -> 0.05 | D18: Percentual de alocação de recebiveis para investimentos
B19: Investimento[Outros] | C19: =cel_investimento*cel_receita_total -> 779.7475 | D19: Valor bruto reservado para os demais valores de investimento
B20: ano_inicio | C20: =YEAR(cel_data_inicio) -> 2026 | D20: ano do periodo
B21: semana | C21: =WEEKNUM(DATE(YEAR(cel_data_inicio), MONTH(cel_data_inicio), 1), 2) -> 14 | D21: Numero da primeira semana do perio escolhido
B22: data_fim | C22: =cel_data_inicio+cel_priodo_tamanho -> 46162 | D22: Data de fim do periodo
B23: Semana1 | C23: =cel_data_inicio -> 46132 | D23: Data de inicio da primeira semana
B24: Semana2 | C24: =cel_semana1+7 -> 46139 | D24: Data de inicio da segunda semana
B25: Semana3 | C25: =cel_semana2+7 -> 46146 | D25: Data de inicio da terceira semana
B26: Semana4 | C26: =cel_semana3+7 -> 46153 | D26: Data de inicio da quarta semana
B27: seamana1_perc | C27: =(cel_semana2-cel_semana1)/(cel_data_fim-cel_data_inicio) -> 0.23333333 | D27: Percentual de alocação para primeira semana
B28: semana2_perc | C28: =(cel_semana3-cel_semana2)/(cel_data_fim-cel_data_inicio) -> 0.23333333 | D28: Percentual de alocação para segunda semana
B29: semana3_perc | C29: =(cel_semana4-cel_semana3)/(cel_data_fim-cel_data_inicio) -> 0.23333333 | D29: Percentual de alocação para terceira semana
B30: semana4_perc | C30: =(cel_data_fim-cel_semana4)/(cel_data_fim-cel_data_inicio) -> 0.3 | D30: Percentual de alocação para quarta semana
B31: recebiveis_atrasdos | C31: =SUMIFS(tb_recebiveis[valor],tb_recebiveis[Data],"<"&data_inicio,tb_recebiveis[Recebido],"",tb_recebiveis[Categoria],"<>"&"Patrimonio*") -> 0 | D31: Soma de todos os recebíveis atrasados não pagos
B32: recebiveis_atual | C32: =(cel_recebiveis_atual_concreto+cel_recebiveis_atual_planejado) -> 0
B33: recebiveis_atual_planejado | C33: =SUMIFS(tb_recebiveis[valor],tb_recebiveis[Data],">="&data_inicio,tb_recebiveis[Data],"<="&data_fim,tb_recebiveis[Recebido],"",tb_recebiveis[Categoria],"<>"&"Patrimonio*") -> 0 | D33: Soma de todos os recebiveis do periodo atual ainda não recebidos
B34: recebiveis_atual_concreto | C34: =SUMIFS(tb_recebiveis[valor],tb_recebiveis[Data],">="&data_inicio,tb_recebiveis[Data],"<="&data_fim,tb_recebiveis[Recebido],">="&data_inicio,tb_recebiveis[Recebido],"<="&data_fim,tb_recebiveis[Recebido],"<>"&"",tb_recebiveis[Categoria],"<>"&"Patrimonio*") -> 0 | D34: Soma de todos os recebiveis do periodo atual já recebidos
B35: recebiveis_adiantados | C35: =SUMIFS(tb_recebiveis[valor],tb_recebiveis[Data],">"&data_fim,tb_recebiveis[Recebido],">="&data_inicio,tb_recebiveis[Recebido],"<="&data_fim,tb_recebiveis[Categoria],"<>"&"Patrimonio*") -> 0 | D35: Soma de todos os recebiveis futuros que estão sendo pagos no periodo atual
B36: recebiveis_futuros | C36: =SUMIFS(tb_recebiveis[valor],tb_recebiveis[Data],">"&data_fim,tb_recebiveis[Recebido],"",tb_recebiveis[Categoria],"<>"&"Patrimonio*") -> 0 | D36: Soma de todos os recebíveis futuros ainda não pagos
B37: patrimonio_atrasdos | C37: =SUMIFS(tb_recebiveis[valor],tb_recebiveis[Data],"<"&data_inicio,tb_recebiveis[Recebido],"",tb_recebiveis[Categoria],"="&"Patrimonio*") -> 0 | D37: Valores relacionados a patrimonio que ainda não foram executados
B38: patrimonio_atual_planejado | C38: =SUMIFS(tb_recebiveis[valor],tb_recebiveis[Data],">="&data_inicio,tb_recebiveis[Data],"<="&data_fim,tb_recebiveis[Recebido],"",tb_recebiveis[Categoria],"="&"Patrimonio*") -> 0 | D38: Valores relacionados a patrimonio que serão executados no periodo atual
B39: patrimonio_atual_concreto | C39: =SUMIFS(tb_recebiveis[valor],tb_recebiveis[Data],">="&data_inicio,tb_recebiveis[Data],"<="&data_fim,tb_recebiveis[Recebido],">="&data_inicio,tb_recebiveis[Recebido],"<="&data_fim,tb_recebiveis[Recebido],"<>"&"",tb_recebiveis[Categoria],"="&"Patrimonio*") -> 0 | D39: Valores relacionados a patrimonio que foram executados no periodo atual
B40: patrimonio_adiantados | C40: =SUMIFS(tb_recebiveis[valor],tb_recebiveis[Data],">"&data_fim,tb_recebiveis[Recebido],">="&data_inicio,tb_recebiveis[Recebido],"<="&data_fim,tb_recebiveis[Categoria],"="&"Patrimonio*") -> 0 | D40: Valores relacionados a patrimonio que foram executados de forma adiantada
B41: patrimonio_futuros | C41: =SUMIFS(tb_recebiveis[valor],tb_recebiveis[Data],">"&data_fim,tb_recebiveis[Recebido],"",tb_recebiveis[Categoria],"="&"Patrimonio*") -> 0 | D41: Valores relacionados a patrimonio planejados para serem executados
...
